Workbook

Sheet Estimates_of_Use_of_Water2
A1: name | B1: year | C1: region | D1: y_diff | E1: avg_y_diff | F1: pop_n | G1: pop_u | H1: wat_bas_n | I1: wat_bas_n_rounded | J1: ARC_n_full | K1: ARC=0_n | L1: ARC < 0_n | M1: ARC > 0_n | N1: ARC_n | O1: wat_lim_n | P1: wat_unimp_n | Q1: wat_sur_n | R1: wat_bas_r | S1: wat_bas_r_rounded | T1: ARC_r_full | U1: ARC=0_r | V1: ARC<0_r | W1: ARC>0_r | X1: ARC_r | Y1: wat_lim_r | Z1: wat_unimp_r | AA1: wat_sur_r | AB1: wat_bas_u | AC1: wat_bas_u_rounded | AD1: ARC_u_full | AE1: ARC=0_u | AF1: ARC<0_u | AG1: ARC>0_u | AH1: ARC_u | AI1: wat_lim_u | AJ1: wat_unimp_u | AK1: wat_sur_u | AL1: ARC_diff
A2: Afghanistan | B2: 2015 | C2: =VLOOKUP(A2, Regions!A:B, 2, FALSE) -> South Asia | D2: =IF(A3=A2, B3-B2, "") -> 5 | E2: =IF(AND(A2=A3,), AVERAGEIF(A2:A3, A3, B2:B3), "") -> 2017.5 | F2: 34413.60156 | G2: 24.802999 | H2: 61.339781 | I2: =MIN(ROUND(H2, 0), 100) -> 61 | J2: =IF(AND(A2=A3, I2>99, I3>99), "full access", "") | K2: =IF(AND(I2=0, J2<>"full access"), "ARC=0", "") | L2: =IF(AND(I2<0, J2<>"full access"), "ARC<0", "") | M2: =IF(AND(I2>0, J2<>"full access"), "ARC>0", "") -> ARC>0 | N2: =IF(A3=A2, (H3 - H2)/(B3 - B2), "") -> 2.7503265 | O2: 3.5111995 | P2: 22.168784 | Q2: 12.980236 | R2: 52.988502 | S2: =MIN(ROUND(R2, 0), 100) -> 53 | T2: =IF(AND(A2=A3, S2>99, S3>99), "full access", "") | U2: =IF(AND(S2=0, Q2<>"full access"), "ARC=0", "") | V2: =IF(AND(S2<0, Q2<>"full access"), "ARC<0", "") | W2: =IF(AND(S2>0, Q2<>"full access"), "ARC>0", "") -> ARC>0 | X2: =IF(A3=A2, (R3 - R2)/(B3 - B2), "") -> 2.6678826 | Y2: 3.8611366 | Z2: 26.553268 | AA2: 16.597094 | AB2: 86.658941 | AC2: =MIN(ROUND(AB2, 0), 100) -> 87 | AD2: =IF(AND(A2=A3, AC2>99, AC3>99), "full access", "") | AE2: =IF(AND(AC2=0, X2<>"full access"), "ARC=0", "") | AF2: =IF(AND(AC2<0, X2<>"full access"), "ARC<0", "") | AG2: =IF(AND(AC2>0, X2<>"full access"), "ARC>0", "") -> ARC>0 | AH2: =IF(A3=A2, (AB3 - AB2)/(B3 - B2), "") -> 2.6682119 | AI2: 2.4502706 | AJ2: 8.8760357 | AK2: 2.014752987 | AL2: =IF(AND(MOD(ROW(), 2) = 0, ISNUMBER(X2), ISNUMBER(AH2)), X2 - AH2, "") -> -0.000329218
A3: Afghanistan | B3: 2020 | C3: =VLOOKUP(A3, Regions!A:B, 2, FALSE) -> South Asia | D3: =IF(A4=A3, B4-B3, "") | E3: =IF(AND(A3=A4,), AVERAGEIF(A3:A4, A4, B3:B4), "") | F3: 38928.33984 | G3: 26.025999 | H3: 75.091413 | I3: =MIN(ROUND(H3, 0), 100) -> 75 | J3: =IF(AND(A3=A4, I3>99, I4>99), "full access", "") | K3: =IF(AND(I3=0, J3<>"full access"), "ARC=0", "") | L3: =IF(AND(I3<0, J3<>"full access"), "ARC<0", "") | M3: =IF(AND(I3>0, J3<>"full access"), "ARC>0", "") -> ARC>0 | N3: =IF(A4=A3, (H4 - H3)/(B4 - B3), "") | O3: 1.4475417 | P3: 14.560263 | Q3: 8.9007822 | R3: 66.327915 | S3: =MIN(ROUND(R3, 0), 100) -> 66 | T3: =IF(AND(A3=A4, S3>99, S4>99), "full access", "") | U3: =IF(AND(S3=0, Q3<>"full access"), "ARC=0", "") | V3: =IF(AND(S3<0, Q3<>"full access"), "ARC<0", "") | W3: =IF(AND(S3>0, Q3<>"full access"), "ARC>0", "") -> ARC>0 | X3: =IF(A4=A3, (R4 - R3)/(B4 - B3), "") | Y3: 1.9568249 | Z3: 19.682949 | AA3: 12.032311 | AB3: 100 | AC3: =MIN(ROUND(AB3, 0), 100) -> 100 | AD3: =IF(AND(A3=A4, AC3>99, AC4>99), "full access", "") | AE3: =IF(AND(AC3=0, X3<>"full access"), "ARC=0", "") | AF3: =IF(AND(AC3<0, X3<>"full access"), "ARC<0", "") | AG3: =IF(AND(AC3>0, X3<>"full access"), "ARC>0", "") -> ARC>0 | AH3: =IF(A4=A3, (AB4 - AB3)/(B4 - B3), "") | AI3: 0 | AJ3: 0 | AK3: 0 | AL3: =IF(AND(MOD(ROW(), 2) = 0, ISNUMBER(X3), ISNUMBER(AH3)), X3 - AH3, "")
A4: Albania | B4: 2015 | C4: =VLOOKUP(A4, Regions!A:B, 2, FALSE) -> Europe & Central Asia | D4: =IF(A5=A4, B5-B4, "") -> 5 | E4: =IF(AND(A4=A5,), AVERAGEIF(A4:A5, A5, B4:B5), "") -> 2017.5 | F4: 2890.523926 | G4: 57.433998 | H4: 93.394325 | I4: =MIN(ROUND(H4, 0), 100) -> 93 | J4: =IF(AND(A4=A5, I4>99, I5>99), "full access", "") | K4: =IF(AND(I4=0, J4<>"full access"), "ARC=0", "") | L4: =IF(AND(I4<0, J4<>"full access"), "ARC<0", "") | M4: =IF(AND(I4>0, J4<>"full access"), "ARC>0", "") -> ARC>0 | N4: =IF(A5=A4, (H5 - H4)/(B5 - B4), "") -> 0.3347427 | O4: 3.6263837 | P4: 2.979291 | Q4: 0 | R4: 90.627275 | S4: =MIN(ROUND(R4, 0), 100) -> 91 | T4: =IF(AND(A4=A5, S4>99, S5>99), "full access", "") | U4: =IF(AND(S4=0, Q4<>"full access"), "ARC=0", "") | V4: =IF(AND(S4<0, Q4<>"full access"), "ARC<0", "") | W4: =IF(AND(S4>0, Q4<>"full access"), "ARC>0", "") -> ARC>0 | X4: =IF(A5=A4, (R5 - R4)/(B5 - B4), "") -> 0.69281669 | Y4: 5.2631726 | Z4: 4.1095527 | AA4: 0 | AB4: 95.445067 | AC4: =MIN(ROUND(AB4, 0), 100) -> 95 | AD4: =IF(AND(A4=A5, AC4>99, AC5>99), "full access", "") | AE4: =IF(AND(AC4=0, X4<>"full access"), "ARC=0", "") | AF4: =IF(AND(AC4<0, X4<>"full access"), "ARC<0", "") | AG4: =IF(AND(AC4>0, X4<>"full access"), "ARC>0", "") -> ARC>0 | AH4: =IF(A5=A4, (AB5 - AB4)/(B5 - B4), "") -> 0.043748432 | AI4: 2.4133118 | AJ4: 2.1416212 | AK4: 0 | AL4: =IF(AND(MOD(ROW(), 2) = 0, ISNUMBER(X4), ISNUMBER(AH4)), X4 - AH4, "") -> 0.64906826
A5: Albania | B5: 2020 | C5: =VLOOKUP(A5, Regions!A:B, 2, FALSE) -> Europe & Central Asia | D5: =IF(A6=A5, B6-B5, "") | E5: =IF(AND(A5=A6,), AVERAGEIF(A5:A6, A6, B5:B6), "") | F5: 2877.800049 | G5: 62.112 | H5: 95.068039 | I5: =MIN(ROUND(H5, 0), 100) -> 95 | J5: =IF(AND(A5=A6, I5>99, I6>99), "full access", "") | K5: =IF(AND(I5=0, J5<>"full access"), "ARC=0", "") | L5: =IF(AND(I5<0, J5<>"full access"), "ARC<0", "") | M5: =IF(AND(I5>0, J5<>"full access"), "ARC>0", "") -> ARC>0 | N5: =IF(A6=A5, (H6 - H5)/(B6 - B5), "") | O5: 1.8846561 | P5: 3.0473051 | Q5: 0 | R5: 94.091358 | S5: =MIN(ROUND(R5, 0), 100) -> 94 | T5: =IF(AND(A5=A6, S5>99, S6>99), "full access", "") | U5: =IF(AND(S5=0, Q5<>"full access"), "ARC=0", "") | V5: =IF(AND(S5<0, Q5<>"full access"), "ARC<0", "") | W5: =IF(AND(S5>0, Q5<>"full access"), "ARC>0", "") -> ARC>0 | X5: =IF(A6=A5, (R6 - R5)/(B6 - B5), "") | Y5: 2.305265 | Z5: 3.603377 | AA5: 0 | AB5: 95.663809 | AC5: =MIN(ROUND(AB5, 0), 100) -> 96 | AD5: =IF(AND(A5=A6, AC5>99, AC6>99), "full access", "") | AE5: =IF(AND(AC5=0, X5<>"full access"), "ARC=0", "") | AF5: =IF(AND(AC5<0, X5<>"full access"), "ARC<0", "") | AG5: =IF(AND(AC5>0, X5<>"full access"), "ARC>0", "") -> ARC>0 | AH5: =IF(A6=A5, (AB6 - AB5)/(B6 - B5), "") | AI5: 1.6280868 | AJ5: 2.7081041 | AK5: 0 | AL5: =IF(AND(MOD(ROW(), 2) = 0, ISNUMBER(X5), ISNUMBER(AH5)), X5 - AH5, "")
A6: Algeria | B6: 2015 | C6: =VLOOKUP(A6, Regions!A:B, 2, FALSE) -> Middle East & North Africa | D6: =IF(A7=A6, B7-B6, "") -> 5 | E6: =IF(AND(A6=A7,), AVERAGEIF(A6:A7, A7, B6:B7), "") -> 2017.5 | F6: 39728.01953 | G6: 70.848 | H6: 93.409562 | I6: =MIN(ROUND(H6, 0), 100) -> 93 | J6: =IF(AND(A6=A7, I6>99, I7>99), "full access", "") | K6: =IF(AND(I6=0, J6<>"full access"), "ARC=0", "") | L6: =IF(AND(I6<0, J6<>"full access"), "ARC<0", "") | M6: =IF(AND(I6>0, J6<>"full access"), "ARC>0", "") -> ARC>0 | N6: =IF(A7=A6, (H7 - H6)/(B7 - B6), "") -> 0.20555369 | O6: 5.1577809 | P6: 1.2754647 | Q6: 0.15719289 | R6: 88.352707 | S6: =MIN(ROUND(R6, 0), 100) -> 88 | T6: =IF(AND(A6=A7, S6>99, S7>99), "full access", "") | U6: =IF(AND(S6=0, Q6<>"full access"), "ARC=0", "") | V6: =IF(AND(S6<0, Q6<>"full access"), "ARC<0", "") | W6: =IF(AND(S6>0, Q6<>"full access"), "ARC>0", "") -> ARC>0 | X6: =IF(A7=A6, (R7 - R6)/(B7 - B6), "") -> 0.33696621 | Y6: 8.6857531 | Z6: 2.5804318 | AA6: 0.38110822 | AB6: 95.490315 | AC6: =MIN(ROUND(AB6, 0), 100) -> 95 | AD6: =IF(AND(A6=A7, AC6>99, AC7>99), "full access", "") | AE6: =IF(AND(AC6=0, X6<>"full access"), "ARC=0", "") | AF6: =IF(AND(AC6<0, X6<>"full access"), "ARC<0", "") | AG6: =IF(AND(AC6>0, X6<>"full access"), "ARC>0", "") -> ARC>0 | AH6: =IF(A7=A6, (AB7 - AB6)/(B7 - B6), "") -> 0.10288423 | AI6: 3.7061173 | AJ6: 0.73851009 | AK6: 0.06505789753 | AL6: =IF(AND(MOD(ROW(), 2) = 0, ISNUMBER(X6), ISNUMBER(AH6)), X6 - AH6, "") -> 0.23408198
A7: Algeria | B7: 2020 | C7: =VLOOKUP(A7, Regions!A:B, 2, FALSE) -> Middle East & North Africa | D7: =IF(A8=A7, B8-B7, "") | E7: =IF(AND(A7=A8,), AVERAGEIF(A7:A8, A8, B7:B8), "") | F7: 43851.04297 | G7: 73.733002 | H7: 94.43733 | I7: =MIN(ROUND(H7, 0), 100) -> 94 | J7: =IF(AND(A7=A8, I7>99, I8>99), "full access", "") | K7: =IF(AND(I7=0, J7<>"full access"), "ARC=0", "") | L7: =IF(AND(I7<0, J7<>"full access"), "ARC<0", "") | M7: =IF(AND(I7>0, J7<>"full access"), "ARC>0", "") -> ARC>0 | N7: =IF(A8=A7, (H8 - H7)/(B8 - B7), "") | O7: 4.9858808 | P7: 0.53183666 | Q7: 0.044952533 | R7: 90.037538 | S7: =MIN(ROUND(R7, 0), 100) -> 90 | T7: =IF(AND(A7=A8, S7>99, S8>99), "full access", "") | U7: =IF(AND(S7=0, Q7<>"full access"), "ARC=0", "") | V7: =IF(AND(S7<0, Q7<>"full access"), "ARC<0", "") | W7: =IF(AND(S7>0, Q7<>"full access"), "ARC>0", "") -> ARC>0 | X7: =IF(A8=A7, (R8 - R7)/(B8 - B7), "") | Y7: 8.7967221 | Z7: 0.99460303 | AA7: 0.17113693 | AB7: 96.004736 | AC7: =MIN(ROUND(AB7, 0), 100) -> 96 | AD7: =IF(AND(A7=A8, AC7>99, AC8>99), "full access", "") | AE7: =IF(AND(AC7=0, X7<>"full access"), "ARC=0", "") | AF7: =IF(AND(AC7<0, X7<>"full access"), "ARC<0", "") | AG7: =IF(AND(AC7>0, X7<>"full access"), "ARC>0", "") -> ARC>0 | AH7: =IF(A8=A7, (AB8 - AB7)/(B8 - B7), "") | AI7: 3.6282886 | AJ7: 0.36697555 | AK7: 0 | AL7: =IF(AND(MOD(ROW(), 2) = 0, ISNUMBER(X7), ISNUMBER(AH7)), X7 - AH7, "")
A8: American Samoa | B8: 2015 | C8: =VLOOKUP(A8, Regions!A:B, 2, FALSE) -> East Asia & Pacific | D8: =IF(A9=A8, B9-B8, "") -> 5 | E8: =IF(AND(A8=A9,), AVERAGEIF(A8:A9, A9, B8:B9), "") -> 2017.5 | F8: 55.80599976 | G8: 87.238007 | H8: 99.619103 | I8: =MIN(ROUND(H8, 0), 100) -> 100 | J8: =IF(AND(A8=A9, I8>99, I9>99), "full access", "") -> full access | K8: =IF(AND(I8=0, J8<>"full access"), "ARC=0", "") | L8: =IF(AND(I8<0, J8<>"full access"), "ARC<0", "") | M8: =IF(AND(I8>0, J8<>"full access"), "ARC>0", "") | N8: =IF(A9=A8, (H9 - H8)/(B9 - B8), "") -> 0.030933702 | O8: 0 | P8: 0.38089685 | Q8: 0 | S8: =MIN(ROUND(R8, 0), 100) -> 0 | T8: =IF(AND(A8=A9, S8>99, S9>99), "full access", "") | U8: =IF(AND(S8=0, Q8<>"full access"), "ARC=0", "") -> ARC=0 | V8: =IF(AND(S8<0, Q8<>"full access"), "ARC<0", "") | W8: =IF(AND(S8>0, Q8<>"full access"), "ARC>0", "") | X8: =IF(A9=A8, (R9 - R8)/(B9 - B8), "") -> 0 | AC8: =MIN(ROUND(AB8, 0), 100) -> 0 | AD8: =IF(AND(A8=A9, AC8>99, AC9>99), "full access", "") | AE8: =IF(AND(AC8=0, X8<>"full access"), "ARC=0", "") -> ARC=0 | AF8: =IF(AND(AC8<0, X8<>"full access"), "ARC<0", "") | AG8: =IF(AND(AC8>0, X8<>"full access"), "ARC>0", "") | AH8: =IF(A9=A8, (AB9 - AB8)/(B9 - B8), "") -> 0 | AL8: =IF(AND(MOD(ROW(), 2) = 0, ISNUMBER(X8), ISNUMBER(AH8)), X8 - AH8, "") -> 0
A9: American Samoa | B9: 2020 | C9: =VLOOKUP(A9, Regions!A:B, 2, FALSE) -> East Asia & Pacific | D9: =IF(A10=A9, B10-B9, "") | E9: =IF(AND(A9=A10,), AVERAGEIF(A9:A10, A10, B9:B10), "") | F9: 55.1969986 | G9: 87.153 | H9: 99.773772 | I9: =MIN(ROUND(H9, 0), 100) -> 100 | J9: =IF(AND(A9=A10, I9>99, I10>99), "full access", "") | K9: =IF(AND(I9=0, J9<>"full access"), "ARC=0", "") | L9: =IF(AND(I9<0, J9<>"full access"), "ARC<0", "") | M9: =IF(AND(I9>0, J9<>"full access"), "ARC>0", "") -> ARC>0 | N9: =IF(A10=A9, (H10 - H9)/(B10 - B9), "") | O9: 0 | P9: 0.22622834 | Q9: 0 | S9: =MIN(ROUND(R9, 0), 100) -> 0 | T9: =IF(AND(A9=A10, S9>99, S10>99), "full access", "") | U9: =IF(AND(S9=0, Q9<>"full access"), "ARC=0", "") -> ARC=0 | V9: =IF(AND(S9<0, Q9<>"full access"), "ARC<0", "") | W9: =IF(AND(S9>0, Q9<>"full access"), "ARC>0", "") | X9: =IF(A10=A9, (R10 - R9)/(B10 - B9), "") | AC9: =MIN(ROUND(AB9, 0), 100) -> 0 | AD9: =IF(AND(A9=A10, AC9>99, AC10>99), "full access", "") | AE9: =IF(AND(AC9=0, X9<>"full access"), "ARC=0", "") -> ARC=0 | AF9: =IF(AND(AC9<0, X9<>"full access"), "ARC<0", "") | AG9: =IF(AND(AC9>0, X9<>"full access"), "ARC>0", "") | AH9: =IF(A10=A9, (AB10 - AB9)/(B10 - B9), "") | AL9: =IF(AND(MOD(ROW(), 2) = 0, ISNUMBER(X9), ISNUMBER(AH9)), X9 - AH9, "")
A10: Andorra | B10: 2015 | C10: =VLOOKUP(A10, Regions!A:B, 2, FALSE) -> Europe & Central Asia | D10: =IF(A11=A10, B11-B10, "") -> 5 | E10: =IF(AND(A10=A11,), AVERAGEIF(A10:A11, A11, B10:B11), "") -> 2017.5 | F10: 77.99299622 | G10: 88.344994 | H10: 99.999998 | I10: =MIN(ROUND(H10, 0), 100) -> 100 | J10: =IF(AND(A10=A11, I10>99, I11>99), "full access", "") -> full access | K10: =IF(AND(I10=0, J10<>"full access"), "ARC=0", "") | L10: =IF(AND(I10<0, J10<>"full access"), "ARC<0", "") | M10: =IF(AND(I10>0, J10<>"full access"), "ARC>0", "") | N10: =IF(A11=A10, (H11 - H10)/(B11 - B10), "") -> 1.23e-06 | O10: 0 | P10: 2.4455384e-06 | Q10: 0 | R10: 100 | S10: =MIN(ROUND(R10, 0), 100) -> 100 | T10: =IF(AND(A10=A11, S10>99, S11>99), "full access", "") -> full access | U10: =IF(AND(S10=0, Q10<>"full access"), "ARC=0", "") | V10: =IF(AND(S10<0, Q10<>"full access"), "ARC<0", "") | W10: =IF(AND(S10>0, Q10<>"full access"), "ARC>0", "") -> ARC>0 | X10: =IF(A11=A10, (R11 - R10)/(B11 - B10), "") -> 0 | Y10: 0 | Z10: 0 | AA10: 0 | AB10: 100 | AC10: =MIN(ROUND(AB10, 0), 100) -> 100 | AD10: =IF(AND(A10=A11, AC10>99, AC11>99), "full access", "") -> full access | AE10: =IF(AND(AC10=0, X10<>"full access"), "ARC=0", "") | AF10: =IF(AND(AC10<0, X10<>"full access"), "ARC<0", "") | AG10: =IF(AND(AC10>0, X10<>"full access"), "ARC>0", "") -> ARC>0 | AH10: =IF(A11=A10, (AB11 - AB10)/(B11 - B10), "") -> 0 | AI10: 0 | AJ10: 0 | AK10: 0 | AL10: =IF(AND(MOD(ROW(), 2) = 0, ISNUMBER(X10), ISNUMBER(AH10)), X10 - AH10, "") -> 0
A11: Andorra | B11: 2020 | C11: =VLOOKUP(A11, Regions!A:B, 2, FALSE) -> Europe & Central Asia | D11: =IF(A12=A11, B12-B11, "") | E11: =IF(AND(A11=A12,), AVERAGEIF(A11:A12, A12, B11:B12), "") | F11: 77.26499939 | G11: 87.916 | H11: 100 | I11: =MIN(ROUND(H11, 0), 100) -> 100 | J11: =IF(AND(A11=A12, I11>99, I12>99), "full access", "") | K11: =IF(AND(I11=0, J11<>"full access"), "ARC=0", "") | L11: =IF(AND(I11<0, J11<>"full access"), "ARC<0", "") | M11: =IF(AND(I11>0, J11<>"full access"), "ARC>0", "") -> ARC>0 | N11: =IF(A12=A11, (H12 - H11)/(B12 - B11), "") | O11: 0 | P11: 0 | Q11: 0 | R11: 100 | S11: =MIN(ROUND(R11, 0), 100) -> 100 | T11: =IF(AND(A11=A12, S11>99, S12>99), "full access", "") | U11: =IF(AND(S11=0, Q11<>"full access"), "ARC=0", "") | V11: =IF(AND(S11<0, Q11<>"full access"), "ARC<0", "") | W11: =IF(AND(S11>0, Q11<>"full access"), "ARC>0", "") -> ARC>0 | X11: =IF(A12=A11, (R12 - R11)/(B12 - B11), "") | Y11: 0 | Z11: 0 | AA11: 0 | AB11: 100 | AC11: =MIN(ROUND(AB11, 0), 100) -> 100 | AD11: =IF(AND(A11=A12, AC11>99, AC12>99), "full access", "") | AE11: =IF(AND(AC11=0, X11<>"full access"), "ARC=0", "") | AF11: =IF(AND(AC11<0, X11<>"full access"), "ARC<0", "") | AG11: =IF(AND(AC11>0, X11<>"full access"), "ARC>0", "") -> ARC>0 | AH11: =IF(A12=A11, (AB12 - AB11)/(B12 - B11), "") | AI11: 0 | AJ11: 0 | AK11: 0 | AL11: =IF(AND(MOD(ROW(), 2) = 0, ISNUMBER(X11), ISNUMBER(AH11)), X11 - AH11, "")
A12: Angola | B12: 2015 | C12: =VLOOKUP(A12, Regions!A:B, 2, FALSE) -> Sub-Saharan Africa | D12: =IF(A13=A12, B13-B12, "") -> 5 | E12: =IF(AND(A12=A13,), AVERAGEIF(A12:A13, A13, B12:B13), "") -> 2017.5 | F12: 27884.38086 | G12: 63.445995 | H12: 54.316928 | I12: =MIN(ROUND(H12, 0), 100) -> 54 | J12: =IF(AND(A12=A13, I12>99, I13>99), "full access", "") | K12: =IF(AND(I12=0, J12<>"full access"), "ARC=0", "") | L12: =IF(AND(I12<0, J12<>"full access"), "ARC<0", "") | M12: =IF(AND(I12>0, J12<>"full access"), "ARC>0", "") -> ARC>0 | N12: =IF(A13=A12, (H13 - H12)/(B13 - B12), "") -> 0.57016185 | O12: 11.368619 | P12: 17.372356 | Q12: 16.942097 | R12: 26.714369 | S12: =MIN(ROUND(R12, 0), 100) -> 27 | T12: =IF(AND(A12=A13, S12>99, S13>99), "full access", "") | U12: =IF(AND(S12=0, Q12<>"full access"), "ARC=0", "") | V12: =IF(AND(S12<0, Q12<>"full access"), "ARC<0", "") | W12: =IF(AND(S12>0, Q12<>"full access"), "ARC>0", "") -> ARC>0 | X12: =IF(A13=A12, (R13 - R12)/(B13 - B12), "") -> 0.21877144 | Y12: 9.9310693 | Z12: 21.725308 | AA12: 41.629254 | AB12: 70.219965 | AC12: =MIN(ROUND(AB12, 0), 100) -> 70 | AD12: =IF(AND(A12=A13, AC12>99, AC13>99), "full access", "") | AE12: =IF(AND(AC12=0, X12<>"full access"), "ARC=0", "") | AF12: =IF(AND(AC12<0, X12<>"full access"), "ARC<0", "") | AG12: =IF(AND(AC12>0, X12<>"full access"), "ARC>0", "") -> ARC>0 | AH12: =IF(A13=A12, (AB13 - AB12)/(B13 - B12), "") -> 0.3046367 | AI12: 12.196853 | AJ12: 14.864431 | AK12: 2.718749921 | AL12: =IF(AND(MOD(ROW(), 2) = 0, ISNUMBER(X12), ISNUMBER(AH12)), X12 - AH12, "") -> -0.085865258
A13: Angola | B13: 2020 | C13: =VLOOKUP(A13, Regions!A:B, 2, FALSE) -> Sub-Saharan Africa | D13: =IF(A14=A13, B14-B13, "") | E13: =IF(AND(A13=A14,), AVERAGEIF(A13:A14, A14, B13:B14), "") | F13: 32866.26953 | G13: 66.824997 | H13: 57.167738 | I13: =MIN(ROUND(H13, 0), 100) -> 57 | J13: =IF(AND(A13=A14, I13>99, I14>99), "full access", "") | K13: =IF(AND(I13=0, J13<>"full access"), "ARC=0", "") | L13: =IF(AND(I13<0, J13<>"full access"), "ARC<0", "") | M13: =IF(AND(I13>0, J13<>"full access"), "ARC>0", "") -> ARC>0 | N13: =IF(A14=A13, (H14 - H13)/(B14 - B13), "") | O13: 9.2873499 | P13: 19.450825 | Q13: 14.094087 | R13: 27.808227 | S13: =MIN(ROUND(R13, 0), 100) -> 28 | T13: =IF(AND(A13=A14, S13>99, S14>99), "full access", "") | U13: =IF(AND(S13=0, Q13<>"full access"), "ARC=0", "") | V13: =IF(AND(S13<0, Q13<>"full access"), "ARC<0", "") | W13: =IF(AND(S13>0, Q13<>"full access"), "ARC>0", "") -> ARC>0 | X13: =IF(A14=A13, (R14 - R13)/(B14 - B13), "") | Y13: 8.7404884 | Z13: 22.933153 | AA13: 40.518132 | AB13: 71.743149 | AC13: =MIN(ROUND(AB13, 0), 100) -> 72 | AD13: =IF(AND(A13=A14, AC13>99, AC14>99), "full access", "") | AE13: =IF(AND(AC13=0, X13<>"full access"), "ARC=0", "") | AF13: =IF(AND(AC13<0, X13<>"full access"), "ARC<0", "") | AG13: =IF(AND(AC13>0, X13<>"full access"), "ARC>0", "") -> ARC>0 | AH13: =IF(A14=A13, (AB14 - AB13)/(B14 - B13), "") | AI13: 9.5588375 | AJ13: 17.722035 | AK13: 0.9759791629 | AL13: =IF(AND(MOD(ROW(), 2) = 0, ISNUMBER(X13), ISNUMBER(AH13)), X13 - AH13, "")
A14: Anguilla | B14: 2015 | C14: =VLOOKUP(A14, Regions!A:B, 2, FALSE) -> Latin America & Caribbean | D14: =IF(A15=A14, B15-B14, "") -> 2 | E14: =IF(AND(A14=A15,), AVERAGEIF(A14:A15, A15, B14:B15), "") -> 2016 | F14: 14.27900028 | G14: 100 | H14: 97.482274 | I14: =MIN(ROUND(H14, 0), 100) -> 97 | J14: =IF(AND(A14=A15, I14>99, I15>99), "full access", "") | K14: =IF(AND(I14=0, J14<>"full access"), "ARC=0", "") | L14: =IF(AND(I14<0, J14<>"full access"), "ARC<0", "") | M14: =IF(AND(I14>0, J14<>"full access"), "ARC>0", "") -> ARC>0 | N14: =IF(A15=A14, (H15 - H14)/(B15 - B14), "") -> 0 | O14: 0 | P14: 2.5177258 | Q14: 0 | S14: =MIN(ROUND(R14, 0), 100) -> 0 | T14: =IF(AND(A14=A15, S14>99, S15>99), "full access", "") | U14: =IF(AND(S14=0, Q14<>"full access"), "ARC=0", "") -> ARC=0 | V14: =IF(AND(S14<0, Q14<>"full access"), "ARC<0", "") | W14: =IF(AND(S14>0, Q14<>"full access"), "ARC>0", "") | X14: =IF(A15=A14, (R15 - R14)/(B15 - B14), "") -> 0 | AB14: 97.482274 | AC14: =MIN(ROUND(AB14, 0), 100) -> 97 | AD14: =IF(AND(A14=A15, AC14>99, AC15>99), "full access", "") | AE14: =IF(AND(AC14=0, X14<>"full access"), "ARC=0", "") | AF14: =IF(AND(AC14<0, X14<>"full access"), "ARC<0", "") | AG14: =IF(AND(AC14>0, X14<>"full access"), "ARC>0", "") -> ARC>0 | AH14: =IF(A15=A14, (AB15 - AB14)/(B15 - B14), "") -> 0 | AI14: 0 | AJ14: 2.5177258 | AK14: 0 | AL14: =IF(AND(MOD(ROW(), 2) = 0, ISNUMBER(X14), ISNUMBER(AH14)), X14 - AH14, "") -> 0
A15: Anguilla | B15: 2017 | C15: =VLOOKUP(A15, Regions!A:B, 2, FALSE) -> Latin America & Caribbean | D15: =IF(A16=A15, B16-B15, "") | E15: =IF(AND(A15=A16,), AVERAGEIF(A15:A16, A16, B15:B16), "") | F15: 14.5880003 | G15: 100 | H15: 97.482274 | I15: =MIN(ROUND(H15, 0), 100) -> 97 | J15: =IF(AND(A15=A16, I15>99, I16>99), "full access", "") | K15: =IF(AND(I15=0, J15<>"full access"), "ARC=0", "") | L15: =IF(AND(I15<0, J15<>"full access"), "ARC<0", "") | M15: =IF(AND(I15>0, J15<>"full access"), "ARC>0", "") -> ARC>0 | N15: =IF(A16=A15, (H16 - H15)/(B16 - B15), "") | O15: 0 | P15: 2.5177258 | Q15: 0 | S15: =MIN(ROUND(R15, 0), 100) -> 0 | T15: =IF(AND(A15=A16, S15>99, S16>99), "full access", "") | U15: =IF(AND(S15=0, Q15<>"full access"), "ARC=0", "") -> ARC=0 | V15: =IF(AND(S15<0, Q15<>"full access"), "ARC<0", "") | W15: =IF(AND(S15>0, Q15<>"full access"), "ARC>0", "") | X15: =IF(A16=A15, (R16 - R15)/(B16 - B15), "") | AB15: 97.482274 | AC15: =MIN(ROUND(AB15, 0), 100) -> 97 | AD15: =IF(AND(A15=A16, AC15>99, AC16>99), "full access", "") | AE15: =IF(AND(AC15=0, X15<>"full access"), "ARC=0", "") | AF15: =IF(AND(AC15<0, X15<>"full access"), "ARC<0", "") | AG15: =IF(AND(AC15>0, X15<>"full access"), "ARC>0", "") -> ARC>0 | AH15: =IF(A16=A15, (AB16 - AB15)/(B16 - B15), "") | AI15: 0 | AJ15: 2.5177258 | AK15: 0 | AL15: =IF(AND(MOD(ROW(), 2) = 0, ISNUMBER(X15), ISNUMBER(AH15)), X15 - AH15, "")
A16: Antigua and Barbuda | B16: 2015 | C16: =VLOOKUP(A16, Regions!A:B, 2, FALSE) -> Latin America & Caribbean | D16: =IF(A17=A16, B17-B16, "") -> 2 | E16: =IF(AND(A16=A17,), AVERAGEIF(A16:A17, A17, B16:B17), "") -> 2016 | F16: 93.57099915 | G16: 25 | H16: 96.739186 | I16: =MIN(ROUND(H16, 0), 100) -> 97 | J16: =IF(AND(A16=A17, I16>99, I17>99), "full access", "") | K16: =IF(AND(I16=0, J16<>"full access"), "ARC=0", "") | L16: =IF(AND(I16<0, J16<>"full access"), "ARC<0", "") | M16: =IF(AND(I16>0, J16<>"full access"), "ARC>0", "") -> ARC>0 | N16: =IF(A17=A16, (H17 - H16)/(B17 - B16), "") -> 0 | O16: 0 | P16: 3.1663476 | Q16: 0.094466114 | S16: =MIN(ROUND(R16, 0), 100) -> 0 | T16: =IF(AND(A16=A17, S16>99, S17>99), "full access", "") | U16: =IF(AND(S16=0, Q16<>"full access"), "ARC=0", "") -> ARC=0 | V16: =IF(AND(S16<0, Q16<>"full access"), "ARC<0", "") | W16: =IF(AND(S16>0, Q16<>"full access"), "ARC>0", "") | X16: =IF(A17=A16, (R17 - R16)/(B17 - B16), "") -> 0 | AC16: =MIN(ROUND(AB16, 0), 100) -> 0 | AD16: =IF(AND(A16=A17, AC16>99, AC17>99), "full access", "") | AE16: =IF(AND(AC16=0, X16<>"full access"), "ARC=0", "") -> ARC=0 | AF16: =IF(AND(AC16<0, X16<>"full access"), "ARC<0", "") | AG16: =IF(AND(AC16>0, X16<>"full access"), "ARC>0", "") | AH16: =IF(A17=A16, (AB17 - AB16)/(B17 - B16), "") -> 0 | AL16: =IF(AND(MOD(ROW(), 2) = 0, ISNUMBER(X16), ISNUMBER(AH16)), X16 - AH16, "") -> 0
A17: Antigua and Barbuda | B17: 2017 | C17: =VLOOKUP(A17, Regions!A:B, 2, FALSE) -> Latin America & Caribbean | D17: =IF(A18=A17, B18-B17, "") | E17: =IF(AND(A17=A18,), AVERAGEIF(A17:A18, A18, B17:B18), "") | F17: 95.42500305 | G17: 24.713001 | H17: 96.739186 | I17: =MIN(ROUND(H17, 0), 100) -> 97 | J17: =IF(AND(A17=A18, I17>99, I18>99), "full access", "") | K17: =IF(AND(I17=0, J17<>"full access"), "ARC=0", "") | L17: =IF(AND(I17<0, J17<>"full access"), "ARC<0", "") | M17: =IF(AND(I17>0, J17<>"full access"), "ARC>0", "") -> ARC>0 | N17: =IF(A18=A17, (H18 - H17)/(B18 - B17), "") | O17: 0 | P17: 3.1663476 | Q17: 0.094466114 | S17: =MIN(ROUND(R17, 0), 100) -> 0 | T17: =IF(AND(A17=A18, S17>99, S18>99), "full access", "") | U17: =IF(AND(S17=0, Q17<>"full access"), "ARC=0", "") -> ARC=0 | V17: =IF(AND(S17<0, Q17<>"full access"), "ARC<0", "") | W17: =IF(AND(S17>0, Q17<>"full access"), "ARC>0", "") | X17: =IF(A18=A17, (R18 - R17)/(B18 - B17), "") | AC17: =MIN(ROUND(AB17, 0), 100) -> 0 | AD17: =IF(AND(A17=A18, AC17>99, AC18>99), "full access", "") | AE17: =IF(AND(AC17=0, X17<>"full access"), "ARC=0", "") -> ARC=0 | AF17: =IF(AND(AC17<0, X17<>"full access"), "ARC<0", "") | AG17: =IF(AND(AC17>0, X17<>"full access"), "ARC>0", "") | AH17: =IF(A18=A17, (AB18 - AB17)/(B18 - B17), "") | AL17: =IF(AND(MOD(ROW(), 2) = 0, ISNUMBER(X17), ISNUMBER(AH17)), X17 - AH17, "")
A18: Argentina | B18: 2015 | C18: =VLOOKUP(A18, Regions!A:B, 2, FALSE) -> Latin America & Caribbean | D18: =IF(A19=A18, B19-B18, "") -> 5 | E18: =IF(AND(A18=A19,), AVERAGEIF(A18:A19, A19, B18:B19), "") -> 2017.5 | F18: 43075.41406 | G18: 91.502998 | H18: 98.966588 | I18: =MIN(ROUND(H18, 0), 100) -> 99 | J18: =IF(AND(A18=A19, I18>99, I19>99), "full access", "") | K18: =IF(AND(I18=0, J18<>"full access"), "ARC=0", "") | L18: =IF(AND(I18<0, J18<>"full access"), "ARC<0", "") | M18: =IF(AND(I18>0, J18<>"full access"), "ARC>0", "") -> ARC>0 | N18: =IF(A19=A18, (H19 - H18)/(B19 - B18), "") -> -19.793318 | O18: 0 | P18: 0.66491438 | Q18: 0.36849747 | R18: 92.98366 | S18: =MIN(ROUND(R18, 0), 100) -> 93 | T18: =IF(AND(A18=A19, S18>99, S19>99), "full access", "") | U18: =IF(AND(S18=0, Q18<>"full access"), "ARC=0", "") | V18: =IF(AND(S18<0, Q18<>"full access"), "ARC<0", "") | W18: =IF(AND(S18>0, Q18<>"full access"), "ARC>0", "") -> ARC>0 | X18: =IF(A19=A18, (R19 - R18)/(B19 - B18), "") -> -18.596732 | Y18: 0 | Z18: 2.6795449 | AA18: 4.3367951 | AB18: 99.522163 | AC18: =MIN(ROUND(AB18, 0), 100) -> 100 | AD18: =IF(AND(A18=A19, AC18>99, AC19>99), "full access", "") -> full access | AE18: =IF(AND(AC18=0, X18<>"full access"), "ARC=0", "") | AF18: =IF(AND(AC18<0, X18<>"full access"), "ARC<0", "") | AG18: =IF(AND(AC18>0, X18<>"full access"), "ARC>0", "") -> ARC>0 | AH18: =IF(A19=A18, (AB19 - AB18)/(B19 - B18), "") -> 0.05365152 | AI18: 0 | AJ18: 0.47783695 | AK18: 0 | AL18: =IF(AND(MOD(ROW(), 2) = 0, ISNUMBER(X18), ISNUMBER(AH18)), X18 - AH18, "") -> -18.650384
A19: Argentina | B19: 2020 | C19: =VLOOKUP(A19, Regions!A:B, 2, FALSE) -> Latin America & Caribbean | D19: =IF(A20=A19, B20-B19, "") | E19: =IF(AND(A19=A20,), AVERAGEIF(A19:A20, A20, B19:B20), "") | F19: 45195.77734 | G19: 92.111 | I19: =MIN(ROUND(H19, 0), 100) -> 0 | J19: =IF(AND(A19=A20, I19>99, I20>99), "full access", "") | K19: =IF(AND(I19=0, J19<>"full access"), "ARC=0", "") -> ARC=0 | L19: =IF(AND(I19<0, J19<>"full access"), "ARC<0", "") | M19: =IF(AND(I19>0, J19<>"full access"), "ARC>0", "") | N19: =IF(A20=A19, (H20 - H19)/(B20 - B19), "") | S19: =MIN(ROUND(R19, 0), 100) -> 0 | T19: =IF(AND(A19=A20, S19>99, S20>99), "full access", "") | U19: =IF(AND(S19=0, Q19<>"full access"), "ARC=0", "") -> ARC=0 | V19: =IF(AND(S19<0, Q19<>"full access"), "ARC<0", "") | W19: =IF(AND(S19>0, Q19<>"full access"), "ARC>0", "") | X19: =IF(A20=A19, (R20 - R19)/(B20 - B19), "") | AB19: 99.790421 | AC19: =MIN(ROUND(AB19, 0), 100) -> 100 | AD19: =IF(AND(A19=A20, AC19>99, AC20>99), "full access", "") | AE19: =IF(AND(AC19=0, X19<>"full access"), "ARC=0", "") | AF19: =IF(AND(AC19<0, X19<>"full access"), "ARC<0", "") | AG19: =IF(AND(AC19>0, X19<>"full access"), "ARC>0", "") -> ARC>0 | AH19: =IF(A20=A19, (AB20 - AB19)/(B20 - B19), "") | AI19: 0 | AJ19: 0.20957935 | AK19: 0 | AL19: =IF(AND(MOD(ROW(), 2) = 0, ISNUMBER(X19), ISNUMBER(AH19)), X19 - AH19, "")
A20: Armenia | B20: 2015 | C20: =VLOOKUP(A20, Regions!A:B, 2, FALSE) -> Europe & Central Asia | D20: =IF(A21=A20, B21-B20, "") -> 5 | E20: =IF(AND(A20=A21,), AVERAGEIF(A20:A21, A21, B20:B21), "") -> 2017.5 | F20: 2925.559082 | G20: 63.085003 | H20: 99.552567 | I20: =MIN(ROUND(H20, 0), 100) -> 100 | J20: =IF(AND(A20=A21, I20>99, I21>99), "full access", "") -> full access | K20: =IF(AND(I20=0, J20<>"full access"), "ARC=0", "") | L20: =IF(AND(I20<0, J20<>"full access"), "ARC<0", "") | M20: =IF(AND(I20>0, J20<>"full access"), "ARC>0", "") | N20: =IF(A21=A20, (H21 - H20)/(B21 - B20), "") -> 0.083722798 | O20: 0 | P20: 0.098505084 | Q20: 0.34892822 | R20: 99.054779 | S20: =MIN(ROUND(R20, 0), 100) -> 99 | T20: =IF(AND(A20=A21, S20>99, S21>99), "full access", "") | U20: =IF(AND(S20=0, Q20<>"full access"), "ARC=0", "") | V20: =IF(AND(S20<0, Q20<>"full access"), "ARC<0", "") | W20: =IF(AND(S20>0, Q20<>"full access"), "ARC>0", "") -> ARC>0 | X20: =IF(A21=A20, (R21 - R20)/(B21 - B20), "") -> 0.18904415 | Y20: 0 | Z20: 0 | AA20: 0.94522073 | AB20: 99.843853 | AC20: =MIN(ROUND(AB20, 0), 100) -> 100 | AD20: =IF(AND(A20=A21, AC20>99, AC21>99), "full access", "") -> full access | AE20: =IF(AND(AC20=0, X20<>"full access"), "ARC=0", "") | AF20: =IF(AND(AC20<0, X20<>"full access"), "ARC<0", "") | AG20: =IF(AND(AC20>0, X20<>"full access"), "ARC>0", "") -> ARC>0 | AH20: =IF(A21=A20, (AB21 - AB20)/(B21 - B20), "") -> 0.022125564 | AI20: 0 | AJ20: 0.1561466 | AK20: 0 | AL20: =IF(AND(MOD(ROW(), 2) = 0, ISNUMBER(X20), ISNUMBER(AH20)), X20 - AH20, "") -> 0.16691858
A21: Armenia | B21: 2020 | C21: =VLOOKUP(A21, Regions!A:B, 2, FALSE) -> Europe & Central Asia | D21: =IF(A22=A21, B22-B21, "") | E21: =IF(AND(A21=A22,), AVERAGEIF(A21:A22, A22, B21:B22), "") | F21: 2963.233887 | G21: 63.313 | H21: 99.971181 | I21: =MIN(ROUND(H21, 0), 100) -> 100 | J21: =IF(AND(A21=A22, I21>99, I22>99), "full access", "") | K21: =IF(AND(I21=0, J21<>"full access"), "ARC=0", "") | L21: =IF(AND(I21<0, J21<>"full access"), "ARC<0", "") | M21: =IF(AND(I21>0, J21<>"full access"), "ARC>0", "") -> ARC>0 | N21: =IF(A22=A21, (H22 - H21)/(B22 - B21), "") | O21: 0 | P21: 0.028819308 | Q21: 0 | R21: 100 | S21: =MIN(ROUND(R21, 0), 100) -> 100 | T21: =IF(AND(A21=A22, S21>99, S22>99), "full access", "") | U21: =IF(AND(S21=0, Q21<>"full access"), "ARC=0", "") | V21: =IF(AND(S21<0, Q21<>"full access"), "ARC<0", "") | W21: =IF(AND(S21>0, Q21<>"full access"), "ARC>0", "") -> ARC>0 | X21: =IF(A22=A21, (R22 - R21)/(B22 - B21), "") | Y21: 0 | Z21: 0 | AA21: 0 | AB21: 99.954481 | AC21: =MIN(ROUND(AB21, 0), 100) -> 100 | AD21: =IF(AND(A21=A22, AC21>99, AC22>99), "full access", "") | AE21: =IF(AND(AC21=0, X21<>"full access"), "ARC=0", "") | AF21: =IF(AND(AC21<0, X21<>"full access"), "ARC<0", "") | AG21: =IF(AND(AC21>0, X21<>"full access"), "ARC>0", "") -> ARC>0 | AH21: =IF(A22=A21, (AB22 - AB21)/(B22 - B21), "") | AI21: 0 | AJ21: 0.045518784 | AK21: 0 | AL21: =IF(AND(MOD(ROW(), 2) = 0, ISNUMBER(X21), ISNUMBER(AH21)), X21 - AH21, "")
A22: Aruba | B22: 2015 | C22: =VLOOKUP(A22, Regions!A:B, 2, FALSE) -> Latin America & Caribbean | D22: =IF(A23=A22, B23-B22, "") -> 1 | E22: =IF(AND(A22=A23,), AVERAGEIF(A22:A23, A23, B22:B23), "") -> 2015.5 | F22: 104.3389969 | G22: 43.108002 | H22: 97.869023 | I22: =MIN(ROUND(H22, 0), 100) -> 98 | J22: =IF(AND(A22=A23, I22>99, I23>99), "full access", "") | K22: =IF(AND(I22=0, J22<>"full access"), "ARC=0", "") | L22: =IF(AND(I22<0, J22<>"full access"), "ARC<0", "") | M22: =IF(AND(I22>0, J22<>"full access"), "ARC>0", "") -> ARC>0 | N22: =IF(A23=A22, (H23 - H22)/(B23 - B22), "") -> 0 | O22: 0 | P22: 1.9599362 | Q22: 0.17104041 | S22: =MIN(ROUND(R22, 0), 100) -> 0 | T22: =IF(AND(A22=A23, S22>99, S23>99), "full access", "") | U22: =IF(AND(S22=0, Q22<>"full access"), "ARC=0", "") -> ARC=0 | V22: =IF(AND(S22<0, Q22<>"full access"), "ARC<0", "") | W22: =IF(AND(S22>0, Q22<>"full access"), "ARC>0", "") | X22: =IF(A23=A22, (R23 - R22)/(B23 - B22), "") -> 0 | AC22: =MIN(ROUND(AB22, 0), 100) -> 0 | AD22: =IF(AND(A22=A23, AC22>99, AC23>99), "full access", "") | AE22: =IF(AND(AC22=0, X22<>"full access"), "ARC=0", "") -> ARC=0 | AF22: =IF(AND(AC22<0, X22<>"full access"), "ARC<0", "") | AG22: =IF(AND(AC22>0, X22<>"full access"), "ARC>0", "") | AH22: =IF(A23=A22, (AB23 - AB22)/(B23 - B22), "") -> 0 | AL22: =IF(AND(MOD(ROW(), 2) = 0, ISNUMBER(X22), ISNUMBER(AH22)), X22 - AH22, "") -> 0
A23: Aruba | B23: 2016 | C23: =VLOOKUP(A23, Regions!A:B, 2, FALSE) -> Latin America & Caribbean | D23: =IF(A24=A23, B24-B23, "") | E23: =IF(AND(A23=A24,), AVERAGEIF(A23:A24, A24, B23:B24), "") | F23: 104.8649979 | G23: 43.191998 | H23: 97.869023 | I23: =MIN(ROUND(H23, 0), 100) -> 98 | J23: =IF(AND(A23=A24, I23>99, I24>99), "full access", "") | K23: =IF(AND(I23=0, J23<>"full access"), "ARC=0", "") | L23: =IF(AND(I23<0, J23<>"full access"), "ARC<0", "") | M23: =IF(AND(I23>0, J23<>"full access"), "ARC>0", "") -> ARC>0 | N23: =IF(A24=A23, (H24 - H23)/(B24 - B23), "") | O23: 0 | P23: 1.9599362 | Q23: 0.17104041 | S23: =MIN(ROUND(R23, 0), 100) -> 0 | T23: =IF(AND(A23=A24, S23>99, S24>99), "full access", "") | U23: =IF(AND(S23=0, Q23<>"full access"), "ARC=0", "") -> ARC=0 | V23: =IF(AND(S23<0, Q23<>"full access"), "ARC<0", "") | W23: =IF(AND(S23>0, Q23<>"full access"), "ARC>0", "") | X23: =IF(A24=A23, (R24 - R23)/(B24 - B23), "") | AC23: =MIN(ROUND(AB23, 0), 100) -> 0 | AD23: =IF(AND(A23=A24, AC23>99, AC24>99), "full access", "") | AE23: =IF(AND(AC23=0, X23<>"full access"), "ARC=0", "") -> ARC=0 | AF23: =IF(AND(AC23<0, X23<>"full access"), "ARC<0", "") | AG23: =IF(AND(AC23>0, X23<>"full access"), "ARC>0", "") | AH23: =IF(A24=A23, (AB24 - AB23)/(B24 - B23), "") | AL23: =IF(AND(MOD(ROW(), 2) = 0, ISNUMBER(X23), ISNUMBER(AH23)), X23 - AH23, "")
A24: Australia | B24: 2015 | C24: =VLOOKUP(A24, Regions!A:B, 2, FALSE) -> East Asia & Pacific | D24: =IF(A25=A24, B25-B24, "") -> 5 | E24: =IF(AND(A24=A25,), AVERAGEIF(A24:A25, A25, B24:B25), "") -> 2017.5 | F24: 23932.49805 | G24: 85.701004 | H24: 99.970006 | I24: =MIN(ROUND(H24, 0), 100) -> 100 | J24: =IF(AND(A24=A25, I24>99, I25>99), "full access", "") -> full access | K24: =IF(AND(I24=0, J24<>"full access"), "ARC=0", "") | L24: =IF(AND(I24<0, J24<>"full access"), "ARC<0", "") | M24: =IF(AND(I24>0, J24<>"full access"), "ARC>0", "") | N24: =IF(A25=A24, (H25 - H24)/(B25 - B24), "") -> -3.877e-05 | O24: 0 | P24: 0.029994331 | Q24: 0 | R24: 100 | S24: =MIN(ROUND(R24, 0), 100) -> 100 | T24: =IF(AND(A24=A25, S24>99, S25>99), "full access", "") -> full access | U24: =IF(AND(S24=0, Q24<>"full access"), "ARC=0", "") | V24: =IF(AND(S24<0, Q24<>"full access"), "ARC<0", "") | W24: =IF(AND(S24>0, Q24<>"full access"), "ARC>0", "") -> ARC>0 | X24: =IF(A25=A24, (R25 - R24)/(B25 - B24), "") -> 0 | Y24: 0 | Z24: 0 | AA24: 0 | AB24: 99.965 | AC24: =MIN(ROUND(AB24, 0), 100) -> 100 | AD24: =IF(AND(A24=A25, AC24>99, AC25>99), "full access", "") -> full access | AE24: =IF(AND(AC24=0, X24<>"full access"), "ARC=0", "") | AF24: =IF(AND(AC24<0, X24<>"full access"), "ARC<0", "") | AG24: =IF(AND(AC24>0, X24<>"full access"), "ARC>0", "") -> ARC>0 | AH24: =IF(A25=A24, (AB25 - AB24)/(B25 - B24), "") -> 0 | AI24: 0 | AJ24: 0.035 | AK24: 0 | AL24: =IF(AND(MOD(ROW(), 2) = 0, ISNUMBER(X24), ISNUMBER(AH24)), X24 - AH24, "") -> 0
A25: Australia | B25: 2020 | C25: =VLOOKUP(A25, Regions!A:B, 2, FALSE) -> East Asia & Pacific | D25: =IF(A26=A25, B26-B25, "") | E25: =IF(AND(A25=A26,), AVERAGEIF(A25:A26, A26, B25:B26), "") | F25: 25499.88086 | G25: 86.240997 | H25: 99.969812 | I25: =MIN(ROUND(H25, 0), 100) -> 100 | J25: =IF(AND(A25=A26, I25>99, I26>99), "full access", "") | K25: =IF(AND(I25=0, J25<>"full access"), "ARC=0", "") | L25: =IF(AND(I25<0, J25<>"full access"), "ARC<0", "") | M25: =IF(AND(I25>0, J25<>"full access"), "ARC>0", "") -> ARC>0 | N25: =IF(A26=A25, (H26 - H25)/(B26 - B25), "") | O25: 0 | P25: 0.030188179 | Q25: 0 | R25: 100 | S25: =MIN(ROUND(R25, 0), 100) -> 100 | T25: =IF(AND(A25=A26, S25>99, S26>99), "full access", "") | U25: =IF(AND(S25=0, Q25<>"full access"), "ARC=0", "") | V25: =IF(AND(S25<0, Q25<>"full access"), "ARC<0", "") | W25: =IF(AND(S25>0, Q25<>"full access"), "ARC>0", "") -> ARC>0 | X25: =IF(A26=A25, (R26 - R25)/(B26 - B25), "") | Y25: 0 | Z25: 0 | AA25: 0 | AB25: 99.965 | AC25: =MIN(ROUND(AB25, 0), 100) -> 100 | AD25: =IF(AND(A25=A26, AC25>99, AC26>99), "full access", "") | AE25: =IF(AND(AC25=0, X25<>"full access"), "ARC=0", "") | AF25: =IF(AND(AC25<0, X25<>"full access"), "ARC<0", "") | AG25: =IF(AND(AC25>0, X25<>"full access"), "ARC>0", "") -> ARC>0 | AH25: =IF(A26=A25, (AB26 - AB25)/(B26 - B25), "") | AI25: 0 | AJ25: 0.035 | AK25: 0 | AL25: =IF(AND(MOD(ROW(), 2) = 0, ISNUMBER(X25), ISNUMBER(AH25)), X25 - AH25, "")
A26: Austria | B26: 2015 | C26: =VLOOKUP(A26, Regions!A:B, 2, FALSE) -> Europe & Central Asia | D26: =IF(A27=A26, B27-B26, "") -> 5 | E26: =IF(AND(A26=A27,), AVERAGEIF(A26:A27, A27, B26:B27), "") -> 2017.5 | F26: 8678.666992 | G26: 57.715 | H26: 100 | I26: =MIN(ROUND(H26, 0), 100) -> 100 | J26: =IF(AND(A26=A27, I26>99, I27>99), "full access", "") -> full access | K26: =IF(AND(I26=0, J26<>"full access"), "ARC=0", "") | L26: =IF(AND(I26<0, J26<>"full access"), "ARC<0", "") | M26: =IF(AND(I26>0, J26<>"full access"), "ARC>0", "") | N26: =IF(A27=A26, (H27 - H26)/(B27 - B26), "") -> 0 | O26: 0 | P26: 0 | Q26: 0 | R26: 100 | S26: =MIN(ROUND(R26, 0), 100) -> 100 | T26: =IF(AND(A26=A27, S26>99, S27>99), "full access", "") -> full access | U26: =IF(AND(S26=0, Q26<>"full access"), "ARC=0", "") | V26: =IF(AND(S26<0, Q26<>"full access"), "ARC<0", "") | W26: =IF(AND(S26>0, Q26<>"full access"), "ARC>0", "") -> ARC>0 | X26: =IF(A27=A26, (R27 - R26)/(B27 - B26), "") -> 0 | Y26: 0 | Z26: 0 | AA26: 0 | AB26: 100 | AC26: =MIN(ROUND(AB26, 0), 100) -> 100 | AD26: =IF(AND(A26=A27, AC26>99, AC27>99), "full access", "") -> full access | AE26: =IF(AND(AC26=0, X26<>"full access"), "ARC=0", "") | AF26: =IF(AND(AC26<0, X26<>"full access"), "ARC<0", "") | AG26: =IF(AND(AC26>0, X26<>"full access"), "ARC>0", "") -> ARC>0 | AH26: =IF(A27=A26, (AB27 - AB26)/(B27 - B26), "") -> 0 | AI26: 0 | AJ26: 0 | AK26: 0 | AL26: =IF(AND(MOD(ROW(), 2) = 0, ISNUMBER(X26), ISNUMBER(AH26)), X26 - AH26, "") -> 0
A27: Austria | B27: 2020 | C27: =VLOOKUP(A27, Regions!A:B, 2, FALSE) -> Europe & Central Asia | D27: =IF(A28=A27, B28-B27, "") | E27: =IF(AND(A27=A28,), AVERAGEIF(A27:A28, A28, B27:B28), "") | F27: 9006.400391 | G27: 58.748001 | H27: 100 | I27: =MIN(ROUND(H27, 0), 100) -> 100 | J27: =IF(AND(A27=A28, I27>99, I28>99), "full access", "") | K27: =IF(AND(I27=0, J27<>"full access"), "ARC=0", "") | L27: =IF(AND(I27<0, J27<>"full access"), "ARC<0", "") | M27: =IF(AND(I27>0, J27<>"full access"), "ARC>0", "") -> ARC>0 | N27: =IF(A28=A27, (H28 - H27)/(B28 - B27), "") | O27: 0 | P27: 0 | Q27: 0 | R27: 100 | S27: =MIN(ROUND(R27, 0), 100) -> 100 | T27: =IF(AND(A27=A28, S27>99, S28>99), "full access", "") | U27: =IF(AND(S27=0, Q27<>"full access"), "ARC=0", "") | V27: =IF(AND(S27<0, Q27<>"full access"), "ARC<0", "") | W27: =IF(AND(S27>0, Q27<>"full access"), "ARC>0", "") -> ARC>0 | X27: =IF(A28=A27, (R28 - R27)/(B28 - B27), "") | Y27: 0 | Z27: 0 | AA27: 0 | AB27: 100 | AC27: =MIN(ROUND(AB27, 0), 100) -> 100 | AD27: =IF(AND(A27=A28, AC27>99, AC28>99), "full access", "") | AE27: =IF(AND(AC27=0, X27<>"full access"), "ARC=0", "") | AF27: =IF(AND(AC27<0, X27<>"full access"), "ARC<0", "") | AG27: =IF(AND(AC27>0, X27<>"full access"), "ARC>0", "") -> ARC>0 | AH27: =IF(A28=A27, (AB28 - AB27)/(B28 - B27), "") | AI27: 0 | AJ27: 0 | AK27: 0 | AL27: =IF(AND(MOD(ROW(), 2) = 0, ISNUMBER(X27), ISNUMBER(AH27)), X27 - AH27, "")
A28: Azerbaijan | B28: 2015 | C28: =VLOOKUP(A28, Regions!A:B, 2, FALSE) -> Europe & Central Asia | D28: =IF(A29=A28, B29-B28, "") -> 5 | E28: =IF(AND(A28=A29,), AVERAGEIF(A28:A29, A29, B28:B29), "") -> 2017.5 | F28: 9622.741211 | G28: 54.714001 | H28: 92.420314 | I28: =MIN(ROUND(H28, 0), 100) -> 92 | J28: =IF(AND(A28=A29, I28>99, I29>99), "full access", "") | K28: =IF(AND(I28=0, J28<>"full access"), "ARC=0", "") | L28: =IF(AND(I28<0, J28<>"full access"), "ARC<0", "") | M28: =IF(AND(I28>0, J28<>"full access"), "ARC>0", "") -> ARC>0 | N28: =IF(A29=A28, (H29 - H28)/(B29 - B28), "") -> 0.72461243 | O28: 1.0022424 | P28: 4.3650895 | Q28: 2.2123541 | R28: 84.143213 | S28: =MIN(ROUND(R28, 0), 100) -> 84 | T28: =IF(AND(A28=A29, S28>99, S29>99), "full access", "") | U28: =IF(AND(S28=0, Q28<>"full access"), "ARC=0", "") | V28: =IF(AND(S28<0, Q28<>"full access"), "ARC<0", "") | W28: =IF(AND(S28>0, Q28<>"full access"), "ARC>0", "") -> ARC>0 | X28: =IF(A29=A28, (R29 - R28)/(B29 - B28), "") -> 1.3565169 | Y28: 2.2131397 | Z28: 8.988206 | AA28: 4.655441 | AB28: 99.271152 | AC28: =MIN(ROUND(AB28, 0), 100) -> 99 | AD28: =IF(AND(A28=A29, AC28>99, AC29>99), "full access", "") | AE28: =IF(AND(AC28=0, X28<>"full access"), "ARC=0", "") | AF28: =IF(AND(AC28<0, X28<>"full access"), "ARC<0", "") | AG28: =IF(AND(AC28>0, X28<>"full access"), "ARC>0", "") -> ARC>0 | AH28: =IF(A29=A28, (AB29 - AB28)/(B29 - B28), "") -> 0.14576959 | AI28: 0 | AJ28: 0.53860203 | AK28: 0.1902459339 | AL28: =IF(AND(MOD(ROW(), 2) = 0, ISNUMBER(X28), ISNUMBER(AH28)), X28 - AH28, "") -> 1.2107473
A29: Azerbaijan | B29: 2020 | C29: =VLOOKUP(A29, Regions!A:B, 2, FALSE) -> Europe & Central Asia | D29: =IF(A30=A29, B30-B29, "") | E29: =IF(AND(A29=A30,), AVERAGEIF(A29:A30, A30, B29:B30), "") | F29: 10139.1748 | G29: 56.397003 | H29: 96.043376 | I29: =MIN(ROUND(H29, 0), 100) -> 96 | J29: =IF(AND(A29=A30, I29>99, I30>99), "full access", "") | K29: =IF(AND(I29=0, J29<>"full access"), "ARC=0", "") | L29: =IF(AND(I29<0, J29<>"full access"), "ARC<0", "") | M29: =IF(AND(I29>0, J29<>"full access"), "ARC>0", "") -> ARC>0 | N29: =IF(A30=A29, (H30 - H29)/(B30 - B29), "") | O29: 1.0427812 | P29: 2.9138427 | Q29: 0 | R29: 90.925798 | S29: =MIN(ROUND(R29, 0), 100) -> 91 | T29: =IF(AND(A29=A30, S29>99, S30>99), "full access", "") | U29: =IF(AND(S29=0, Q29<>"full access"), "ARC=0", "") | V29: =IF(AND(S29<0, Q29<>"full access"), "ARC<0", "") | W29: =IF(AND(S29>0, Q29<>"full access"), "ARC>0", "") -> ARC>0 | X29: =IF(A30=A29, (R30 - R29)/(B30 - B29), "") | Y29: 2.3915357 | Z29: 6.6826664 | AA29: 0 | AB29: 100 | AC29: =MIN(ROUND(AB29, 0), 100) -> 100 | AD29: =IF(AND(A29=A30, AC29>99, AC30>99), "full access", "") | AE29: =IF(AND(AC29=0, X29<>"full access"), "ARC=0", "") | AF29: =IF(AND(AC29<0, X29<>"full access"), "ARC<0", "") | AG29: =IF(AND(AC29>0, X29<>"full access"), "ARC>0", "") -> ARC>0 | AH29: =IF(A30=A29, (AB30 - AB29)/(B30 - B29), "") | AI29: 0 | AJ29: 0 | AK29: 0 | AL29: =IF(AND(MOD(ROW(), 2) = 0, ISNUMBER(X29), ISNUMBER(AH29)), X29 - AH29, "")
A30: Bahamas | B30: 2015 | C30: =VLOOKUP(A30, Regions!A:B, 2, FALSE) -> Latin America & Caribbean | D30: =IF(A31=A30, B31-B30, "") -> 4 | E30: =IF(AND(A30=A31,), AVERAGEIF(A30:A31, A31, B30:B31), "") -> 2017 | F30: 374.2000122 | G30: 82.745995 | H30: 98.886961 | I30: =MIN(ROUND(H30, 0), 100) -> 99 | J30: =IF(AND(A30=A31, I30>99, I31>99), "full access", "") | K30: =IF(AND(I30=0, J30<>"full access"), "ARC=0", "") | L30: =IF(AND(I30<0, J30<>"full access"), "ARC<0", "") | M30: =IF(AND(I30>0, J30<>"full access"), "ARC>0", "") -> ARC>0 | N30: =IF(A31=A30, (H31 - H30)/(B31 - B30), "") -> 0 | O30: 0 | P30: 1.1130395 | Q30: 0 | S30: =MIN(ROUND(R30, 0), 100) -> 0 | T30: =IF(AND(A30=A31, S30>99, S31>99), "full access", "") | U30: =IF(AND(S30=0, Q30<>"full access"), "ARC=0", "") -> ARC=0 | V30: =IF(AND(S30<0, Q30<>"full access"), "ARC<0", "") | W30: =IF(AND(S30>0, Q30<>"full access"), "ARC>0", "") | X30: =IF(A31=A30, (R31 - R30)/(B31 - B30), "") -> 0 | AC30: =MIN(ROUND(AB30, 0), 100) -> 0 | AD30: =IF(AND(A30=A31, AC30>99, AC31>99), "full access", "") | AE30: =IF(AND(AC30=0, X30<>"full access"), "ARC=0", "") -> ARC=0 | AF30: =IF(AND(AC30<0, X30<>"full access"), "ARC<0", "") | AG30: =IF(AND(AC30>0, X30<>"full access"), "ARC>0", "") | AH30: =IF(A31=A30, (AB31 - AB30)/(B31 - B30), "") -> 0 | AL30: =IF(AND(MOD(ROW(), 2) = 0, ISNUMBER(X30), ISNUMBER(AH30)), X30 - AH30, "") -> 0
A31: Bahamas | B31: 2019 | C31: =VLOOKUP(A31, Regions!A:B, 2, FALSE) -> Latin America & Caribbean | D31: =IF(A32=A31, B32-B31, "") | E31: =IF(AND(A31=A32,), AVERAGEIF(A31:A32, A32, B31:B32), "") | F31: 389.4859924 | G31: 83.131996 | H31: 98.886961 | I31: =MIN(ROUND(H31, 0), 100) -> 99 | J31: =IF(AND(A31=A32, I31>99, I32>99), "full access", "") | K31: =IF(AND(I31=0, J31<>"full access"), "ARC=0", "") | L31: =IF(AND(I31<0, J31<>"full access"), "ARC<0", "") | M31: =IF(AND(I31>0, J31<>"full access"), "ARC>0", "") -> ARC>0 | N31: =IF(A32=A31, (H32 - H31)/(B32 - B31), "") | O31: 0 | P31: 1.1130395 | Q31: 0 | S31: =MIN(ROUND(R31, 0), 100) -> 0 | T31: =IF(AND(A31=A32, S31>99, S32>99), "full access", "") | U31: =IF(AND(S31=0, Q31<>"full access"), "ARC=0", "") -> ARC=0 | V31: =IF(AND(S31<0, Q31<>"full access"), "ARC<0", "") | W31: =IF(AND(S31>0, Q31<>"full access"), "ARC>0", "") | X31: =IF(A32=A31, (R32 - R31)/(B32 - B31), "") | AC31: =MIN(ROUND(AB31, 0), 100) -> 0 | AD31: =IF(AND(A31=A32, AC31>99, AC32>99), "full access", "") | AE31: =IF(AND(AC31=0, X31<>"full access"), "ARC=0", "") -> ARC=0 | AF31: =IF(AND(AC31<0, X31<>"full access"), "ARC<0", "") | AG31: =IF(AND(AC31>0, X31<>"full access"), "ARC>0", "") | AH31: =IF(A32=A31, (AB32 - AB31)/(B32 - B31), "") | AL31: =IF(AND(MOD(ROW(), 2) = 0, ISNUMBER(X31), ISNUMBER(AH31)), X31 - AH31, "")
A32: Bahrain | B32: 2015 | C32: =VLOOKUP(A32, Regions!A:B, 2, FALSE) -> Europe & Central Asia | D32: =IF(A33=A32, B33-B32, "") -> 5 | E32: =IF(AND(A32=A33,), AVERAGEIF(A32:A33, A33, B32:B33), "") -> 2017.5 | F32: 1371.853027 | G32: 88.998993 | H32: 100 | I32: =MIN(ROUND(H32, 0), 100) -> 100 | J32: =IF(AND(A32=A33, I32>99, I33>99), "full access", "") -> full access | K32: =IF(AND(I32=0, J32<>"full access"), "ARC=0", "") | L32: =IF(AND(I32<0, J32<>"full access"), "ARC<0", "") | M32: =IF(AND(I32>0, J32<>"full access"), "ARC>0", "") | N32: =IF(A33=A32, (H33 - H32)/(B33 - B32), "") -> 0 | O32: 0 | P32: 0 | Q32: 0 | S32: =MIN(ROUND(R32, 0), 100) -> 0 | T32: =IF(AND(A32=A33, S32>99, S33>99), "full access", "") | U32: =IF(AND(S32=0, Q32<>"full access"), "ARC=0", "") -> ARC=0 | V32: =IF(AND(S32<0, Q32<>"full access"), "ARC<0", "") | W32: =IF(AND(S32>0, Q32<>"full access"), "ARC>0", "") | X32: =IF(A33=A32, (R33 - R32)/(B33 - B32), "") -> 0 | AC32: =MIN(ROUND(AB32, 0), 100) -> 0 | AD32: =IF(AND(A32=A33, AC32>99, AC33>99), "full access", "") | AE32: =IF(AND(AC32=0, X32<>"full access"), "ARC=0", "") -> ARC=0 | AF32: =IF(AND(AC32<0, X32<>"full access"), "ARC<0", "") | AG32: =IF(AND(AC32>0, X32<>"full access"), "ARC>0", "") | AH32: =IF(A33=A32, (AB33 - AB32)/(B33 - B32), "") -> 0 | AL32: =IF(AND(MOD(ROW(), 2) = 0, ISNUMBER(X32), ISNUMBER(AH32)), X32 - AH32, "") -> 0
A33: Bahrain | B33: 2020 | C33: =VLOOKUP(A33, Regions!A:B, 2, FALSE) -> Europe & Central Asia | D33: =IF(A34=A33, B34-B33, "") | E33: =IF(AND(A33=A34,), AVERAGEIF(A33:A34, A34, B33:B34), "") | F33: 1701.583008 | G33: 89.506004 | H33: 100 | I33: =MIN(ROUND(H33, 0), 100) -> 100 | J33: =IF(AND(A33=A34, I33>99, I34>99), "full access", "") | K33: =IF(AND(I33=0, J33<>"full access"), "ARC=0", "") | L33: =IF(AND(I33<0, J33<>"full access"), "ARC<0", "") | M33: =IF(AND(I33>0, J33<>"full access"), "ARC>0", "") -> ARC>0 | N33: =IF(A34=A33, (H34 - H33)/(B34 - B33), "") | O33: 0 | P33: 0 | Q33: 0 | S33: =MIN(ROUND(R33, 0), 100) -> 0 | T33: =IF(AND(A33=A34, S33>99, S34>99), "full access", "") | U33: =IF(AND(S33=0, Q33<>"full access"), "ARC=0", "") -> ARC=0 | V33: =IF(AND(S33<0, Q33<>"full access"), "ARC<0", "") | W33: =IF(AND(S33>0, Q33<>"full access"), "ARC>0", "") | X33: =IF(A34=A33, (R34 - R33)/(B34 - B33), "") | AC33: =MIN(ROUND(AB33, 0), 100) -> 0 | AD33: =IF(AND(A33=A34, AC33>99, AC34>99), "full access", "") | AE33: =IF(AND(AC33=0, X33<>"full access"), "ARC=0", "") -> ARC=0 | AF33: =IF(AND(AC33<0, X33<>"full access"), "ARC<0", "") | AG33: =IF(AND(AC33>0, X33<>"full access"), "ARC>0", "") | AH33: =IF(A34=A33, (AB34 - AB33)/(B34 - B33), "") | AL33: =IF(AND(MOD(ROW(), 2) = 0, ISNUMBER(X33), ISNUMBER(AH33)), X33 - AH33, "")
A34: Bangladesh | B34: 2015 | C34: =VLOOKUP(A34, Regions!A:B, 2, FALSE) -> South Asia | D34: =IF(A35=A34, B35-B34, "") -> 5 | E34: =IF(AND(A34=A35,), AVERAGEIF(A34:A35, A35, B34:B35), "") -> 2017.5 | F34: 156256.2813 | G34: 34.308002 | H34: 97.101602 | I34: =MIN(ROUND(H34, 0), 100) -> 97 | J34: =IF(AND(A34=A35, I34>99, I35>99), "full access", "") | K34: =IF(AND(I34=0, J34<>"full access"), "ARC=0", "") | L34: =IF(AND(I34<0, J34<>"full access"), "ARC<0", "") | M34: =IF(AND(I34>0, J34<>"full access"), "ARC>0", "") -> ARC>0 | N34: =IF(A35=A34, (H35 - H34)/(B35 - B34), "") -> 0.11927156 | O34: 1.087989 | P34: 0.72156166 | Q34: 1.0888469 | R34: 96.773011 | S34: =MIN(ROUND(R34, 0), 100) -> 97 | T34: =IF(AND(A34=A35, S34>99, S35>99), "full access", "") | U34: =IF(AND(S34=0, Q34<>"full access"), "ARC=0", "") | V34: =IF(AND(S34<0, Q34<>"full access"), "ARC<0", "") | W34: =IF(AND(S34>0, Q34<>"full access"), "ARC>0", "") -> ARC>0 | X34: =IF(A35=A34, (R35 - R34)/(B35 - B34), "") -> 0.2214453 | Y34: 1.0462142 | Z34: 0.73174732 | AA34: 1.4490272 | AB34: 97.73078 | AC34: =MIN(ROUND(AB34, 0), 100) -> 98 | AD34: =IF(AND(A34=A35, AC34>99, AC35>99), "full access", "") | AE34: =IF(AND(AC34=0, X34<>"full access"), "ARC=0", "") | AF34: =IF(AND(AC34<0, X34<>"full access"), "ARC<0", "") | AG34: =IF(AND(AC34>0, X34<>"full access"), "ARC>0", "") -> ARC>0 | AH34: =IF(A35=A34, (AB35 - AB34)/(B35 - B34), "") -> -0.065600342 | AI34: 1.1679782 | AJ34: 0.70205843 | AK34: 0.3991837074 | AL34: =IF(AND(MOD(ROW(), 2) = 0, ISNUMBER(X34), ISNUMBER(AH34)), X34 - AH34, "") -> 0.28704564
A35: Bangladesh | B35: 2020 | C35: =VLOOKUP(A35, Regions!A:B, 2, FALSE) -> South Asia | D35: =IF(A36=A35, B36-B35, "") | E35: =IF(AND(A35=A36,), AVERAGEIF(A35:A36, A36, B35:B36), "") | F35: 164689.3906 | G35: 38.177002 | H35: 97.69796 | I35: =MIN(ROUND(H35, 0), 100) -> 98 | J35: =IF(AND(A35=A36, I35>99, I36>99), "full access", "") | K35: =IF(AND(I35=0, J35<>"full access"), "ARC=0", "") | L35: =IF(AND(I35<0, J35<>"full access"), "ARC<0", "") | M35: =IF(AND(I35>0, J35<>"full access"), "ARC>0", "") -> ARC>0 | N35: =IF(A36=A35, (H36 - H35)/(B36 - B35), "") | O35: 1.1564259 | P35: 0.4626557 | Q35: 0.68295817 | R35: 97.880238 | S35: =MIN(ROUND(R35, 0), 100) -> 98 | T35: =IF(AND(A35=A36, S35>99, S36>99), "full access", "") | U35: =IF(AND(S35=0, Q35<>"full access"), "ARC=0", "") | V35: =IF(AND(S35<0, Q35<>"full access"), "ARC<0", "") | W35: =IF(AND(S35>0, Q35<>"full access"), "ARC>0", "") -> ARC>0 | X35: =IF(A36=A35, (R36 - R35)/(B36 - B35), "") | Y35: 0.85810498 | Z35: 0.31648024 | AA35: 0.94517702 | AB35: 97.402778 | AC35: =MIN(ROUND(AB35, 0), 100) -> 97 | AD35: =IF(AND(A35=A36, AC35>99, AC36>99), "full access", "") | AE35: =IF(AND(AC35=0, X35<>"full access"), "ARC=0", "") | AF35: =IF(AND(AC35<0, X35<>"full access"), "ARC<0", "") | AG35: =IF(AND(AC35>0, X35<>"full access"), "ARC>0", "") -> ARC>0 | AH35: =IF(A36=A35, (AB36 - AB35)/(B36 - B35), "") | AI35: 1.6395201 | AJ35: 0.69937521 | AK35: 0.2583266934 | AL35: =IF(AND(MOD(ROW(), 2) = 0, ISNUMBER(X35), ISNUMBER(AH35)), X35 - AH35, "")
A36: Barbados | B36: 2015 | C36: =VLOOKUP(A36, Regions!A:B, 2, FALSE) -> Latin America & Caribbean | D36: =IF(A37=A36, B37-B36, "") -> 5 | E36: =IF(AND(A36=A37,), AVERAGEIF(A36:A37, A37, B36:B37), "") -> 2017.5 | F36: 285.3269958 | G36: 31.248999 | H36: 98.474445 | I36: =MIN(ROUND(H36, 0), 100) -> 98 | J36: =IF(AND(A36=A37, I36>99, I37>99), "full access", "") | K36: =IF(AND(I36=0, J36<>"full access"), "ARC=0", "") | L36: =IF(AND(I36<0, J36<>"full access"), "ARC<0", "") | M36: =IF(AND(I36>0, J36<>"full access"), "ARC>0", "") -> ARC>0 | N36: =IF(A37=A36, (H37 - H36)/(B37 - B36), "") -> 0.008001136 | O36: 0.26749191 | P36: 1.2580634 | Q36: 0 | S36: =MIN(ROUND(R36, 0), 100) -> 0 | T36: =IF(AND(A36=A37, S36>99, S37>99), "full access", "") | U36: =IF(AND(S36=0, Q36<>"full access"), "ARC=0", "") -> ARC=0 | V36: =IF(AND(S36<0, Q36<>"full access"), "ARC<0", "") | W36: =IF(AND(S36>0, Q36<>"full access"), "ARC>0", "") | X36: =IF(A37=A36, (R37 - R36)/(B37 - B36), "") -> 0 | AC36: =MIN(ROUND(AB36, 0), 100) -> 0 | AD36: =IF(AND(A36=A37, AC36>99, AC37>99), "full access", "") | AE36: =IF(AND(AC36=0, X36<>"full access"), "ARC=0", "") -> ARC=0 | AF36: =IF(AND(AC36<0, X36<>"full access"), "ARC<0", "") | AG36: =IF(AND(AC36>0, X36<>"full access"), "ARC>0", "") | AH36: =IF(A37=A36, (AB37 - AB36)/(B37 - B36), "") -> 0 | AL36: =IF(AND(MOD(ROW(), 2) = 0, ISNUMBER(X36), ISNUMBER(AH36)), X36 - AH36, "") -> 0
A37: Barbados | B37: 2020 | C37: =VLOOKUP(A37, Regions!A:B, 2, FALSE) -> Latin America & Caribbean | D37: =IF(A38=A37, B38-B37, "") | E37: =IF(AND(A37=A38,), AVERAGEIF(A37:A38, A38, B37:B38), "") | F37: 287.3710022 | G37: 31.191 | H37: 98.51445 | I37: =MIN(ROUND(H37, 0), 100) -> 99 | J37: =IF(AND(A37=A38, I37>99, I38>99), "full access", "") | K37: =IF(AND(I37=0, J37<>"full access"), "ARC=0", "") | L37: =IF(AND(I37<0, J37<>"full access"), "ARC<0", "") | M37: =IF(AND(I37>0, J37<>"full access"), "ARC>0", "") -> ARC>0 | N37: =IF(A38=A37, (H38 - H37)/(B38 - B37), "") | O37: 0.26760058 | P37: 1.217949 | Q37: 0 | S37: =MIN(ROUND(R37, 0), 100) -> 0 | T37: =IF(AND(A37=A38, S37>99, S38>99), "full access", "") | U37: =IF(AND(S37=0, Q37<>"full access"), "ARC=0", "") -> ARC=0 | V37: =IF(AND(S37<0, Q37<>"full access"), "ARC<0", "") | W37: =IF(AND(S37>0, Q37<>"full access"), "ARC>0", "") | X37: =IF(A38=A37, (R38 - R37)/(B38 - B37), "") | AC37: =MIN(ROUND(AB37, 0), 100) -> 0 | AD37: =IF(AND(A37=A38, AC37>99, AC38>99), "full access", "") | AE37: =IF(AND(AC37=0, X37<>"full access"), "ARC=0", "") -> ARC=0 | AF37: =IF(AND(AC37<0, X37<>"full access"), "ARC<0", "") | AG37: =IF(AND(AC37>0, X37<>"full access"), "ARC>0", "") | AH37: =IF(A38=A37, (AB38 - AB37)/(B38 - B37), "") | AL37: =IF(AND(MOD(ROW(), 2) = 0, ISNUMBER(X37), ISNUMBER(AH37)), X37 - AH37, "")
A38: Belarus | B38: 2015 | C38: =VLOOKUP(A38, Regions!A:B, 2, FALSE) -> Europe & Central Asia | D38: =IF(A39=A38, B39-B38, "") -> 5 | E38: =IF(AND(A38=A39,), AVERAGEIF(A38:A39, A39, B38:B39), "") -> 2017.5 | F38: 9439.423828 | G38: 77.181 | H38: 96.477067 | I38: =MIN(ROUND(H38, 0), 100) -> 96 | J38: =IF(AND(A38=A39, I38>99, I39>99), "full access", "") | K38: =IF(AND(I38=0, J38<>"full access"), "ARC=0", "") | L38: =IF(AND(I38<0, J38<>"full access"), "ARC<0", "") | M38: =IF(AND(I38>0, J38<>"full access"), "ARC>0", "") -> ARC>0 | N38: =IF(A39=A38, (H39 - H38)/(B39 - B38), "") -> 0.011531798 | O38: 3.3001301 | P38: 0.2228028 | Q38: 0 | R38: 98.330672 | S38: =MIN(ROUND(R38, 0), 100) -> 98 | T38: =IF(AND(A38=A39, S38>99, S39>99), "full access", "") | U38: =IF(AND(S38=0, Q38<>"full access"), "ARC=0", "") | V38: =IF(AND(S38<0, Q38<>"full access"), "ARC<0", "") | W38: =IF(AND(S38>0, Q38<>"full access"), "ARC>0", "") -> ARC>0 | X38: =IF(A39=A38, (R39 - R38)/(B39 - B38), "") -> 0.046690142 | Y38: 0.99323911 | Z38: 0.67608929 | AA38: 0 | AB38: 95.929035 | AC38: =MIN(ROUND(AB38, 0), 100) -> 96 | AD38: =IF(AND(A38=A39, AC38>99, AC39>99), "full access", "") | AE38: =IF(AND(AC38=0, X38<>"full access"), "ARC=0", "") | AF38: =IF(AND(AC38<0, X38<>"full access"), "ARC<0", "") | AG38: =IF(AND(AC38>0, X38<>"full access"), "ARC>0", "") -> ARC>0 | AH38: =IF(A39=A38, (AB39 - AB38)/(B39 - B38), "") -> 0.016367688 | AI38: 3.9821754 | AJ38: 0.088789424 | AK38: 0 | AL38: =IF(AND(MOD(ROW(), 2) = 0, ISNUMBER(X38), ISNUMBER(AH38)), X38 - AH38, "") -> 0.030322454
A39: Belarus | B39: 2020 | C39: =VLOOKUP(A39, Regions!A:B, 2, FALSE) -> Europe & Central Asia | D39: =IF(A40=A39, B40-B39, "") | E39: =IF(AND(A39=A40,), AVERAGEIF(A39:A40, A40, B39:B40), "") | F39: 9449.321289 | G39: 79.483002 | H39: 96.534726 | I39: =MIN(ROUND(H39, 0), 100) -> 97 | J39: =IF(AND(A39=A40, I39>99, I40>99), "full access", "") | K39: =IF(AND(I39=0, J39<>"full access"), "ARC=0", "") | L39: =IF(AND(I39<0, J39<>"full access"), "ARC<0", "") | M39: =IF(AND(I39>0, J39<>"full access"), "ARC>0", "") -> ARC>0 | N39: =IF(A40=A39, (H40 - H39)/(B40 - B39), "") | O39: 3.3721195 | P39: 0.093154368 | Q39: 0 | R39: 98.564122 | S39: =MIN(ROUND(R39, 0), 100) -> 99 | T39: =IF(AND(A39=A40, S39>99, S40>99), "full access", "") | U39: =IF(AND(S39=0, Q39<>"full access"), "ARC=0", "") | V39: =IF(AND(S39<0, Q39<>"full access"), "ARC<0", "") | W39: =IF(AND(S39>0, Q39<>"full access"), "ARC>0", "") -> ARC>0 | X39: =IF(A40=A39, (R40 - R39)/(B40 - B39), "") | Y39: 0.9955972 | Z39: 0.44028049 | AA39: 0 | AB39: 96.010874 | AC39: =MIN(ROUND(AB39, 0), 100) -> 96 | AD39: =IF(AND(A39=A40, AC39>99, AC40>99), "full access", "") | AE39: =IF(AND(AC39=0, X39<>"full access"), "ARC=0", "") | AF39: =IF(AND(AC39<0, X39<>"full access"), "ARC<0", "") | AG39: =IF(AND(AC39>0, X39<>"full access"), "ARC>0", "") -> ARC>0 | AH39: =IF(A40=A39, (AB40 - AB39)/(B40 - B39), "") | AI39: 3.9855726 | AJ39: 0.003553732 | AK39: 0 | AL39: =IF(AND(MOD(ROW(), 2) = 0, ISNUMBER(X39), ISNUMBER(AH39)), X39 - AH39, "")
A40: Belgium | B40: 2015 | C40: =VLOOKUP(A40, Regions!A:B, 2, FALSE) -> Europe & Central Asia | D40: =IF(A41=A40, B41-B40, "") -> 5 | E40: =IF(AND(A40=A41,), AVERAGEIF(A40:A41, A41, B40:B41), "") -> 2017.5 | F40: 11287.93066 | G40: 97.875999 | H40: 99.999998 | I40: =MIN(ROUND(H40, 0), 100) -> 100 | J40: =IF(AND(A40=A41, I40>99, I41>99), "full access", "") -> full access | K40: =IF(AND(I40=0, J40<>"full access"), "ARC=0", "") | L40: =IF(AND(I40<0, J40<>"full access"), "ARC<0", "") | M40: =IF(AND(I40>0, J40<>"full access"), "ARC>0", "") | N40: =IF(A41=A40, (H41 - H40)/(B41 - B40), "") -> -2.5e-07 | O40: 0 | P40: 2.2980245e-06 | Q40: 0 | R40: 100 | S40: =MIN(ROUND(R40, 0), 100) -> 100 | T40: =IF(AND(A40=A41, S40>99, S41>99), "full access", "") -> full access | U40: =IF(AND(S40=0, Q40<>"full access"), "ARC=0", "") | V40: =IF(AND(S40<0, Q40<>"full access"), "ARC<0", "") | W40: =IF(AND(S40>0, Q40<>"full access"), "ARC>0", "") -> ARC>0 | X40: =IF(A41=A40, (R41 - R40)/(B41 - B40), "") -> 0 | Y40: 0 | Z40: 0 | AA40: 0 | AB40: 100 | AC40: =MIN(ROUND(AB40, 0), 100) -> 100 | AD40: =IF(AND(A40=A41, AC40>99, AC41>99), "full access", "") -> full access | AE40: =IF(AND(AC40=0, X40<>"full access"), "ARC=0", "") | AF40: =IF(AND(AC40<0, X40<>"full access"), "ARC<0", "") | AG40: =IF(AND(AC40>0, X40<>"full access"), "ARC>0", "") -> ARC>0 | AH40: =IF(A41=A40, (AB41 - AB40)/(B41 - B40), "") -> 0 | AI40: 0 | AJ40: 0 | AK40: 0 | AL40: =IF(AND(MOD(ROW(), 2) = 0, ISNUMBER(X40), ISNUMBER(AH40)), X40 - AH40, "") -> 0
...

Sheet Pivot Table 3

Sheet Countries per Region

Sheet summary sheet
A1: avg_yr_diff | B1: Min_yr_diff | C1: Max_yr_diff | D1: Avg_ARC_n | E1: Avg_ARC_r | F1: Avg_ARC_u | G1: Min_ARC_n | H1: Min_ARC_r | I1: Min_ARC_u | J1: Max_ARC_n | K1: Max_ARC_r | L1: Max_ARC_u | M1: Missing ARC_n | N1: Missing ARC_r | O1: Missing ARC_u | P1: Full_access_n | Q1: Full_access_r | R1: Full_access_u | S1: FullAcess_n | T1: FullAcess_r | U1: FullAcess_u | V1: ARC=0_n | W1: ARC < 0_n | X1: ARC > 0_n | Y1: ARC=0_r | Z1: ARC < 0_r | AA1: ARC > 0_r | AB1: ARC=0_u | AC1: ARC < 0_u | AD1: ARC > 0_u
A2: =ROUND(AVERAGE(Estimates_of_Use_of_Water2!D2:D463), 2) -> 4.8 | B2: =MIN(Estimates_of_Use_of_Water2!D2:D463) -> 1 | C2: =MAX(Estimates_of_Use_of_Water2!D2:D463) -> 5 | D2: =AVERAGE(Estimates_of_Use_of_Water2!N2:N463) -> 0.18866273 | E2: =AVERAGE(Estimates_of_Use_of_Water2!X2:X463) -> 0.098073126 | F2: =AVERAGE(Estimates_of_Use_of_Water2!AH2:AH463) -> 0.12131184 | G2: =MIN(Estimates_of_Use_of_Water2!N2:N463) -> -19.793318 | H2: =MIN(Estimates_of_Use_of_Water2!X2:X463) -> -19.848823 | I2: =MIN(Estimates_of_Use_of_Water2!AH2:AH463) -> -1.6200868 | J2: =MAX(Estimates_of_Use_of_Water2!N2:N463) -> 2.7503265 | K2: =MAX(Estimates_of_Use_of_Water2!X2:X463) -> 2.6678826 | L2: =MAX(Estimates_of_Use_of_Water2!AH2:AH463) -> 2.6682119 | M2: =COUNTBLANK(Estimates_of_Use_of_Water2!N2:N463) -> 231 | N2: =COUNTBLANK(Estimates_of_Use_of_Water2!X2:X463) -> 231 | O2: =COUNTBLANK(Estimates_of_Use_of_Water2!AH2:AH463) -> 231 | P2: =COUNTIFS(Estimates_of_Use_of_Water2!G2:G463, 100, Estimates_of_Use_of_Water2!N2:N463, 0) -> 11 | Q2: =COUNTIFS(Estimates_of_Use_of_Water2!G2:G463, 100, Estimates_of_Use_of_Water2!X2:X463, 0) -> 13 | R2: =COUNTIFS(Estimates_of_Use_of_Water2!G2:G463, 100, Estimates_of_Use_of_Water2!AH2:AH463, 0) -> 11 | S2: =COUNTIF(Estimates_of_Use_of_Water2!J2:J463, "full access") -> 62 | T2: =COUNTIF(Estimates_of_Use_of_Water2!T2:T463, "full access") -> 29 | U2: =COUNTIF(Estimates_of_Use_of_Water2!AD2:AD463, "full access") -> 55 | V2: =COUNTIF(Estimates_of_Use_of_Water2!K2:K463, "ARC=0") -> 3 | W2: =COUNTIF(Estimates_of_Use_of_Water2!L2:L463, "ARC<0") -> 0 | X2: =COUNTIF(Estimates_of_Use_of_Water2!M2:M463, "ARC>0") -> 397 | Y2: =COUNTIF(Estimates_of_Use_of_Water2!U2:U463, "ARC=0") -> 125 | Z2: =COUNTIF(Estimates_of_Use_of_Water2!V2:V463, "ARC<0") -> 0 | AA2: =COUNTIF(Estimates_of_Use_of_Water2!W2:W463, "ARC>0") -> 337 | AB2: =COUNTIF(Estimates_of_Use_of_Water2!AE2:AE463, "ARC=0") -> 100 | AC2: =COUNTIF(Estimates_of_Use_of_Water2!AF2:AF463, "ARC<0") -> 0 | AD2: =COUNTIF(Estimates_of_Use_of_Water2!AG2:AG463, "ARC>0") -> 362 | AE2: =AVERAGEIF(Estimates_of_Use_of_Water2!C2:C463, "RegionName", N2:N463) -> #DIV/0! | AF2: =AVERAGEIF(C2:C463, "RegionName", X2:X463) -> #DIV/0! | AG2: =AVERAGEIF(C2:C463, "RegionName", AH2:AH463) -> #DIV/0!

Sheet Pivot Table 1
A1: #REF!

Sheet Regions
A1: name | B1: region
A2: Afghanistan | B2: South Asia
A3: Albania | B3: Europe & Central Asia
A4: Algeria | B4: Middle East & North Africa
A5: American Samoa | B5: East Asia & Pacific
A6: Andorra | B6: Europe & Central Asia
A7: Angola | B7: Sub-Saharan Africa
A8: Anguilla | B8: Latin America & Caribbean
